2023-11-23 14:33:15,063 [INFO] - Transaction not found
2023-11-23 14:33:15,063 [ERROR] - An error occurred: 
Traceback (most recent call last):
  File "C:\Users\Kianoosh\Projects\KiMiA\VM\api\main.py", line 63, in check_transaction
    raise HTTPException(status_code=404, detail="Transaction not found")
fastapi.exceptions.HTTPException
2023-11-23 15:29:36,970 [ERROR] - An error occurred: (sqlite3.OperationalError) no such column: transactions.card_number
[SQL: SELECT transactions.id, transactions.card_number, transactions.dest_number, transactions.transaction_number 
FROM transactions 
WHERE transactions.card_number = ? AND transactions.dest_number = ? AND transactions.transaction_number = ?]
[parameters: (3951228715566974, 2686085670898567, 258201900343)]
(Background on this error at: https://sqlalche.me/e/20/e3q8)
Traceback (most recent call last):
  File "C:\Users\Kianoosh\Projects\KiMiA\.env\Lib\site-packages\sqlalchemy\engine\base.py", line 1969, in _exec_single_context
    self.dialect.do_execute(
  File "C:\Users\Kianoosh\Projects\KiMiA\.env\Lib\site-packages\sqlalchemy\engine\default.py", line 922, in do_execute
    cursor.execute(statement, parameters)
sqlite3.OperationalError: no such column: transactions.card_number

The above exception was the direct cause of the following exception:

Traceback (most recent call last):
  File "C:\Users\Kianoosh\Projects\KiMiA\VM\api\main.py", line 56, in check_transaction
    result = connection.execute(query)
             ^^^^^^^^^^^^^^^^^^^^^^^^^
  File "C:\Users\Kianoosh\Projects\KiMiA\.env\Lib\site-packages\sqlalchemy\engine\base.py", line 1416, in execute
    return meth(
           ^^^^^
  File "C:\Users\Kianoosh\Projects\KiMiA\.env\Lib\site-packages\sqlalchemy\sql\elements.py", line 516, in _execute_on_connection
    return connection._execute_clauseelement(
           ^^^^^^^^^^^^^^^^^^^^^^^^^^^^^^^^^^
  File "C:\Users\Kianoosh\Projects\KiMiA\.env\Lib\site-packages\sqlalchemy\engine\base.py", line 1639, in _execute_clauseelement
    ret = self._execute_context(
          ^^^^^^^^^^^^^^^^^^^^^^
  File "C:\Users\Kianoosh\Projects\KiMiA\.env\Lib\site-packages\sqlalchemy\engine\base.py", line 1848, in _execute_context
    return self._exec_single_context(
           ^^^^^^^^^^^^^^^^^^^^^^^^^^
  File "C:\Users\Kianoosh\Projects\KiMiA\.env\Lib\site-packages\sqlalchemy\engine\base.py", line 1988, in _exec_single_context
    self._handle_dbapi_exception(
  File "C:\Users\Kianoosh\Projects\KiMiA\.env\Lib\site-packages\sqlalchemy\engine\base.py", line 2343, in _handle_dbapi_exception
    raise sqlalchemy_exception.with_traceback(exc_info[2]) from e
  File "C:\Users\Kianoosh\Projects\KiMiA\.env\Lib\site-packages\sqlalchemy\engine\base.py", line 1969, in _exec_single_context
    self.dialect.do_execute(
  File "C:\Users\Kianoosh\Projects\KiMiA\.env\Lib\site-packages\sqlalchemy\engine\default.py", line 922, in do_execute
    cursor.execute(statement, parameters)
sqlalchemy.exc.OperationalError: (sqlite3.OperationalError) no such column: transactions.card_number
[SQL: SELECT transactions.id, transactions.card_number, transactions.dest_number, transactions.transaction_number 
FROM transactions 
WHERE transactions.card_number = ? AND transactions.dest_number = ? AND transactions.transaction_number = ?]
[parameters: (3951228715566974, 2686085670898567, 258201900343)]
(Background on this error at: https://sqlalche.me/e/20/e3q8)
2023-11-23 15:32:08,878 [ERROR] - An error occurred: card_number
Traceback (most recent call last):
  File "C:\Users\Kianoosh\Projects\KiMiA\.env\Lib\site-packages\sqlalchemy\sql\base.py", line 1633, in __getattr__
    return self._index[key][1]
           ~~~~~~~~~~~^^^^^
KeyError: 'card_number'

The above exception was the direct cause of the following exception:

Traceback (most recent call last):
  File "C:\Users\Kianoosh\Projects\KiMiA\VM\api\main.py", line 52, in check_transaction
    transactions.c.card_number == transaction_data.card_number,
    ^^^^^^^^^^^^^^^^^^^^^^^^^^
  File "C:\Users\Kianoosh\Projects\KiMiA\.env\Lib\site-packages\sqlalchemy\sql\base.py", line 1635, in __getattr__
    raise AttributeError(key) from err
AttributeError: card_number
2023-11-23 15:34:30,807 [INFO] - Transaction found
2023-11-23 15:34:44,792 [INFO] - Transaction not found
2023-11-23 15:34:44,792 [ERROR] - An error occurred: 
Traceback (most recent call last):
  File "C:\Users\Kianoosh\Projects\KiMiA\VM\api\main.py", line 63, in check_transaction
    raise HTTPException(status_code=404, detail="Transaction not found")
fastapi.exceptions.HTTPException
2023-11-23 18:32:58,914 [INFO] - Transaction found
2023-11-23 18:34:29,765 [INFO] - Transaction not found
2023-11-23 18:34:29,765 [ERROR] - An error occurred: 
Traceback (most recent call last):
  File "C:\Users\Kianoosh\Projects\KiMiA\VM\api\main.py", line 63, in check_transaction
    raise HTTPException(status_code=404, detail="Transaction not found")
fastapi.exceptions.HTTPException
2023-11-25 15:14:35,220 [INFO] - Transaction found
2023-11-25 15:16:13,225 [INFO] - Transaction found
2023-11-25 20:18:08,830 [INFO] - Transaction found
